20-06-2018 12:21:20 Working on SSL Certificate
20-06-2018 12:21:20   Checking registered SSL Certificate
20-06-2018 12:21:36 Unable to generate token.
20-06-2018 12:21:36 Invalid username or password.
20-06-2018 12:21:37   ('Unable to generate token.\nInvalid username or password.\n(Error Code: 400)',)
                      ERROR: Unexpected exception thrown
                      Traceback:
                        File "C:\Program Files\ArcGIS\Pro\bin\Python\envs\arcgispro-py3\lib\site-packages\arcgis\gis\__init__.py", line 262, in __init__
                          client_id=self._client_id)
                        File "C:\Program Files\ArcGIS\Pro\bin\Python\envs\arcgispro-py3\lib\site-packages\arcgis\_impl\portalpy.py", line 163, in __init__
                          client_id=client_id)
                        File "C:\Program Files\ArcGIS\Pro\bin\Python\envs\arcgispro-py3\lib\site-packages\arcgis\_impl\connection.py", line 284, in __init__
                          self.login(username, password, expiration, client_id)
                        File "C:\Program Files\ArcGIS\Pro\bin\Python\envs\arcgispro-py3\lib\site-packages\arcgis\_impl\connection.py", line 532, in login
                          newtoken = self.generate_token(username, password, expiration, client_id)
                        File "C:\Program Files\ArcGIS\Pro\bin\Python\envs\arcgispro-py3\lib\site-packages\arcgis\_impl\connection.py", line 397, in generate_token
                          ssl=True, add_token=False)
                        File "C:\Program Files\ArcGIS\Pro\bin\Python\envs\arcgispro-py3\lib\site-packages\arcgis\_impl\connection.py", line 1131, in post
                          self._handle_json_error(resp_json['error'], errorcode)
                        File "C:\Program Files\ArcGIS\Pro\bin\Python\envs\arcgispro-py3\lib\site-packages\arcgis\_impl\connection.py", line 1151, in _handle_json_error
                          raise RuntimeError(errormessage)
                        RuntimeError: Unable to generate token.
                        Invalid username or password.
                        (Error Code: 400)
                        During handling of the above exception, another exception occurred:
                        File "PortalAdmin11.py", line 187, in installSSLCertificate
                          certToInstall = _checkIfCertificateExists(gisInfo, certificateAlias)
                        File "PortalAdmin11.py", line 171, in _checkIfCertificateExists
                          for cert in gisInfo.gis.admin.security.ssl.list():
                        File "PortalAdmin11.py", line 41, in gis
                          self._gis = GIS(self.url, self.username, self.password, verify_cert=False)
                        File "C:\Program Files\ArcGIS\Pro\bin\Python\envs\arcgispro-py3\lib\site-packages\arcgis\gis\__init__.py", line 269, in __init__
                          raise RuntimeError(e.args)
                        RuntimeError: ('Unable to generate token.\nInvalid username or password.\n(Error Code: 400)',)
20-06-2018 12:21:37 Creating roles
20-06-2018 12:22:42 Unable to generate token.
20-06-2018 12:22:42 Invalid username or password.
20-06-2018 12:22:42   ('Unable to generate token.\nInvalid username or password.\n(Error Code: 400)',)
                      ERROR: Unexpected exception thrown
                      Traceback:
                        File "C:\Program Files\ArcGIS\Pro\bin\Python\envs\arcgispro-py3\lib\site-packages\arcgis\gis\__init__.py", line 262, in __init__
                          client_id=self._client_id)
                        File "C:\Program Files\ArcGIS\Pro\bin\Python\envs\arcgispro-py3\lib\site-packages\arcgis\_impl\portalpy.py", line 163, in __init__
                          client_id=client_id)
                        File "C:\Program Files\ArcGIS\Pro\bin\Python\envs\arcgispro-py3\lib\site-packages\arcgis\_impl\connection.py", line 284, in __init__
                          self.login(username, password, expiration, client_id)
                        File "C:\Program Files\ArcGIS\Pro\bin\Python\envs\arcgispro-py3\lib\site-packages\arcgis\_impl\connection.py", line 532, in login
                          newtoken = self.generate_token(username, password, expiration, client_id)
                        File "C:\Program Files\ArcGIS\Pro\bin\Python\envs\arcgispro-py3\lib\site-packages\arcgis\_impl\connection.py", line 397, in generate_token
                          ssl=True, add_token=False)
                        File "C:\Program Files\ArcGIS\Pro\bin\Python\envs\arcgispro-py3\lib\site-packages\arcgis\_impl\connection.py", line 1131, in post
                          self._handle_json_error(resp_json['error'], errorcode)
                        File "C:\Program Files\ArcGIS\Pro\bin\Python\envs\arcgispro-py3\lib\site-packages\arcgis\_impl\connection.py", line 1151, in _handle_json_error
                          raise RuntimeError(errormessage)
                        RuntimeError: Unable to generate token.
                        Invalid username or password.
                        (Error Code: 400)
                        During handling of the above exception, another exception occurred:
                        File "PortalAdmin11.py", line 239, in configureRoles
                          existingRole = _findRole(gisInfo, configRole["name"])
                        File "PortalAdmin11.py", line 226, in _findRole
                          for role in gisInfo.allRoles:
                        File "PortalAdmin11.py", line 62, in allRoles
                          self._allRoles = self.gis.users.roles.all()
                        File "PortalAdmin11.py", line 41, in gis
                          self._gis = GIS(self.url, self.username, self.password, verify_cert=False)
                        File "C:\Program Files\ArcGIS\Pro\bin\Python\envs\arcgispro-py3\lib\site-packages\arcgis\gis\__init__.py", line 269, in __init__
                          raise RuntimeError(e.args)
                        RuntimeError: ('Unable to generate token.\nInvalid username or password.\n(Error Code: 400)',)
20-06-2018 12:22:42 Creating groups
20-06-2018 12:22:43 Unable to generate token.
20-06-2018 12:22:43 'password' must be specified.
20-06-2018 12:22:43   ("Unable to generate token.\n'password' must be specified.\n(Error Code: 400)",)
                      ERROR: Failed to create group ST Captain
                      Traceback:
                        File "C:\Program Files\ArcGIS\Pro\bin\Python\envs\arcgispro-py3\lib\site-packages\arcgis\gis\__init__.py", line 262, in __init__
                          client_id=self._client_id)
                        File "C:\Program Files\ArcGIS\Pro\bin\Python\envs\arcgispro-py3\lib\site-packages\arcgis\_impl\portalpy.py", line 163, in __init__
                          client_id=client_id)
                        File "C:\Program Files\ArcGIS\Pro\bin\Python\envs\arcgispro-py3\lib\site-packages\arcgis\_impl\connection.py", line 284, in __init__
                          self.login(username, password, expiration, client_id)
                        File "C:\Program Files\ArcGIS\Pro\bin\Python\envs\arcgispro-py3\lib\site-packages\arcgis\_impl\connection.py", line 532, in login
                          newtoken = self.generate_token(username, password, expiration, client_id)
                        File "C:\Program Files\ArcGIS\Pro\bin\Python\envs\arcgispro-py3\lib\site-packages\arcgis\_impl\connection.py", line 397, in generate_token
                          ssl=True, add_token=False)
                        File "C:\Program Files\ArcGIS\Pro\bin\Python\envs\arcgispro-py3\lib\site-packages\arcgis\_impl\connection.py", line 1131, in post
                          self._handle_json_error(resp_json['error'], errorcode)
                        File "C:\Program Files\ArcGIS\Pro\bin\Python\envs\arcgispro-py3\lib\site-packages\arcgis\_impl\connection.py", line 1151, in _handle_json_error
                          raise RuntimeError(errormessage)
                        RuntimeError: Unable to generate token.
                        'password' must be specified.
                        (Error Code: 400)
                        During handling of the above exception, another exception occurred:
                        File "PortalAdmin11.py", line 275, in createGroups
                          for extgrp in gisInfo.allGroups:
                        File "PortalAdmin11.py", line 55, in allGroups
                          self._allGroups = self.gis.groups.search()
                        File "PortalAdmin11.py", line 41, in gis
                          self._gis = GIS(self.url, self.username, self.password, verify_cert=False)
                        File "C:\Program Files\ArcGIS\Pro\bin\Python\envs\arcgispro-py3\lib\site-packages\arcgis\gis\__init__.py", line 269, in __init__
                          raise RuntimeError(e.args)
                        RuntimeError: ("Unable to generate token.\n'password' must be specified.\n(Error Code: 400)",)
20-06-2018 12:22:44 Unable to generate token.
20-06-2018 12:22:44 'password' must be specified.
20-06-2018 12:22:44   ("Unable to generate token.\n'password' must be specified.\n(Error Code: 400)",)
                      ERROR: Failed to create group ST User
                      Traceback:
                        File "C:\Program Files\ArcGIS\Pro\bin\Python\envs\arcgispro-py3\lib\site-packages\arcgis\gis\__init__.py", line 262, in __init__
                          client_id=self._client_id)
                        File "C:\Program Files\ArcGIS\Pro\bin\Python\envs\arcgispro-py3\lib\site-packages\arcgis\_impl\portalpy.py", line 163, in __init__
                          client_id=client_id)
                        File "C:\Program Files\ArcGIS\Pro\bin\Python\envs\arcgispro-py3\lib\site-packages\arcgis\_impl\connection.py", line 284, in __init__
                          self.login(username, password, expiration, client_id)
                        File "C:\Program Files\ArcGIS\Pro\bin\Python\envs\arcgispro-py3\lib\site-packages\arcgis\_impl\connection.py", line 532, in login
                          newtoken = self.generate_token(username, password, expiration, client_id)
                        File "C:\Program Files\ArcGIS\Pro\bin\Python\envs\arcgispro-py3\lib\site-packages\arcgis\_impl\connection.py", line 397, in generate_token
                          ssl=True, add_token=False)
                        File "C:\Program Files\ArcGIS\Pro\bin\Python\envs\arcgispro-py3\lib\site-packages\arcgis\_impl\connection.py", line 1131, in post
                          self._handle_json_error(resp_json['error'], errorcode)
                        File "C:\Program Files\ArcGIS\Pro\bin\Python\envs\arcgispro-py3\lib\site-packages\arcgis\_impl\connection.py", line 1151, in _handle_json_error
                          raise RuntimeError(errormessage)
                        RuntimeError: Unable to generate token.
                        'password' must be specified.
                        (Error Code: 400)
                        During handling of the above exception, another exception occurred:
                        File "PortalAdmin11.py", line 275, in createGroups
                          for extgrp in gisInfo.allGroups:
                        File "PortalAdmin11.py", line 55, in allGroups
                          self._allGroups = self.gis.groups.search()
                        File "PortalAdmin11.py", line 41, in gis
                          self._gis = GIS(self.url, self.username, self.password, verify_cert=False)
                        File "C:\Program Files\ArcGIS\Pro\bin\Python\envs\arcgispro-py3\lib\site-packages\arcgis\gis\__init__.py", line 269, in __init__
                          raise RuntimeError(e.args)
                        RuntimeError: ("Unable to generate token.\n'password' must be specified.\n(Error Code: 400)",)
20-06-2018 12:22:45 Unable to generate token.
20-06-2018 12:22:45 'password' must be specified.
20-06-2018 12:22:45   ("Unable to generate token.\n'password' must be specified.\n(Error Code: 400)",)
                      ERROR: Failed to create group The Carousel
                      Traceback:
                        File "C:\Program Files\ArcGIS\Pro\bin\Python\envs\arcgispro-py3\lib\site-packages\arcgis\gis\__init__.py", line 262, in __init__
                          client_id=self._client_id)
                        File "C:\Program Files\ArcGIS\Pro\bin\Python\envs\arcgispro-py3\lib\site-packages\arcgis\_impl\portalpy.py", line 163, in __init__
                          client_id=client_id)
                        File "C:\Program Files\ArcGIS\Pro\bin\Python\envs\arcgispro-py3\lib\site-packages\arcgis\_impl\connection.py", line 284, in __init__
                          self.login(username, password, expiration, client_id)
                        File "C:\Program Files\ArcGIS\Pro\bin\Python\envs\arcgispro-py3\lib\site-packages\arcgis\_impl\connection.py", line 532, in login
                          newtoken = self.generate_token(username, password, expiration, client_id)
                        File "C:\Program Files\ArcGIS\Pro\bin\Python\envs\arcgispro-py3\lib\site-packages\arcgis\_impl\connection.py", line 397, in generate_token
                          ssl=True, add_token=False)
                        File "C:\Program Files\ArcGIS\Pro\bin\Python\envs\arcgispro-py3\lib\site-packages\arcgis\_impl\connection.py", line 1131, in post
                          self._handle_json_error(resp_json['error'], errorcode)
                        File "C:\Program Files\ArcGIS\Pro\bin\Python\envs\arcgispro-py3\lib\site-packages\arcgis\_impl\connection.py", line 1151, in _handle_json_error
                          raise RuntimeError(errormessage)
                        RuntimeError: Unable to generate token.
                        'password' must be specified.
                        (Error Code: 400)
                        During handling of the above exception, another exception occurred:
                        File "PortalAdmin11.py", line 275, in createGroups
                          for extgrp in gisInfo.allGroups:
                        File "PortalAdmin11.py", line 55, in allGroups
                          self._allGroups = self.gis.groups.search()
                        File "PortalAdmin11.py", line 41, in gis
                          self._gis = GIS(self.url, self.username, self.password, verify_cert=False)
                        File "C:\Program Files\ArcGIS\Pro\bin\Python\envs\arcgispro-py3\lib\site-packages\arcgis\gis\__init__.py", line 269, in __init__
                          raise RuntimeError(e.args)
                        RuntimeError: ("Unable to generate token.\n'password' must be specified.\n(Error Code: 400)",)
20-06-2018 12:22:46 Unable to generate token.
20-06-2018 12:22:46 'password' must be specified.
20-06-2018 12:22:46   ("Unable to generate token.\n'password' must be specified.\n(Error Code: 400)",)
                      ERROR: Failed to create group Away Team
                      Traceback:
                        File "C:\Program Files\ArcGIS\Pro\bin\Python\envs\arcgispro-py3\lib\site-packages\arcgis\gis\__init__.py", line 262, in __init__
                          client_id=self._client_id)
                        File "C:\Program Files\ArcGIS\Pro\bin\Python\envs\arcgispro-py3\lib\site-packages\arcgis\_impl\portalpy.py", line 163, in __init__
                          client_id=client_id)
                        File "C:\Program Files\ArcGIS\Pro\bin\Python\envs\arcgispro-py3\lib\site-packages\arcgis\_impl\connection.py", line 284, in __init__
                          self.login(username, password, expiration, client_id)
                        File "C:\Program Files\ArcGIS\Pro\bin\Python\envs\arcgispro-py3\lib\site-packages\arcgis\_impl\connection.py", line 532, in login
                          newtoken = self.generate_token(username, password, expiration, client_id)
                        File "C:\Program Files\ArcGIS\Pro\bin\Python\envs\arcgispro-py3\lib\site-packages\arcgis\_impl\connection.py", line 397, in generate_token
                          ssl=True, add_token=False)
                        File "C:\Program Files\ArcGIS\Pro\bin\Python\envs\arcgispro-py3\lib\site-packages\arcgis\_impl\connection.py", line 1131, in post
                          self._handle_json_error(resp_json['error'], errorcode)
                        File "C:\Program Files\ArcGIS\Pro\bin\Python\envs\arcgispro-py3\lib\site-packages\arcgis\_impl\connection.py", line 1151, in _handle_json_error
                          raise RuntimeError(errormessage)
                        RuntimeError: Unable to generate token.
                        'password' must be specified.
                        (Error Code: 400)
                        During handling of the above exception, another exception occurred:
                        File "PortalAdmin11.py", line 275, in createGroups
                          for extgrp in gisInfo.allGroups:
                        File "PortalAdmin11.py", line 55, in allGroups
                          self._allGroups = self.gis.groups.search()
                        File "PortalAdmin11.py", line 41, in gis
                          self._gis = GIS(self.url, self.username, self.password, verify_cert=False)
                        File "C:\Program Files\ArcGIS\Pro\bin\Python\envs\arcgispro-py3\lib\site-packages\arcgis\gis\__init__.py", line 269, in __init__
                          raise RuntimeError(e.args)
                        RuntimeError: ("Unable to generate token.\n'password' must be specified.\n(Error Code: 400)",)
20-06-2018 12:22:47 Unable to generate token.
20-06-2018 12:22:47 'password' must be specified.
20-06-2018 12:22:47   ("Unable to generate token.\n'password' must be specified.\n(Error Code: 400)",)
                      ERROR: Failed to create group Crew
                      Traceback:
                        File "C:\Program Files\ArcGIS\Pro\bin\Python\envs\arcgispro-py3\lib\site-packages\arcgis\gis\__init__.py", line 262, in __init__
                          client_id=self._client_id)
                        File "C:\Program Files\ArcGIS\Pro\bin\Python\envs\arcgispro-py3\lib\site-packages\arcgis\_impl\portalpy.py", line 163, in __init__
                          client_id=client_id)
                        File "C:\Program Files\ArcGIS\Pro\bin\Python\envs\arcgispro-py3\lib\site-packages\arcgis\_impl\connection.py", line 284, in __init__
                          self.login(username, password, expiration, client_id)
                        File "C:\Program Files\ArcGIS\Pro\bin\Python\envs\arcgispro-py3\lib\site-packages\arcgis\_impl\connection.py", line 532, in login
                          newtoken = self.generate_token(username, password, expiration, client_id)
                        File "C:\Program Files\ArcGIS\Pro\bin\Python\envs\arcgispro-py3\lib\site-packages\arcgis\_impl\connection.py", line 397, in generate_token
                          ssl=True, add_token=False)
                        File "C:\Program Files\ArcGIS\Pro\bin\Python\envs\arcgispro-py3\lib\site-packages\arcgis\_impl\connection.py", line 1131, in post
                          self._handle_json_error(resp_json['error'], errorcode)
                        File "C:\Program Files\ArcGIS\Pro\bin\Python\envs\arcgispro-py3\lib\site-packages\arcgis\_impl\connection.py", line 1151, in _handle_json_error
                          raise RuntimeError(errormessage)
                        RuntimeError: Unable to generate token.
                        'password' must be specified.
                        (Error Code: 400)
                        During handling of the above exception, another exception occurred:
                        File "PortalAdmin11.py", line 275, in createGroups
                          for extgrp in gisInfo.allGroups:
                        File "PortalAdmin11.py", line 55, in allGroups
                          self._allGroups = self.gis.groups.search()
                        File "PortalAdmin11.py", line 41, in gis
                          self._gis = GIS(self.url, self.username, self.password, verify_cert=False)
                        File "C:\Program Files\ArcGIS\Pro\bin\Python\envs\arcgispro-py3\lib\site-packages\arcgis\gis\__init__.py", line 269, in __init__
                          raise RuntimeError(e.args)
                        RuntimeError: ("Unable to generate token.\n'password' must be specified.\n(Error Code: 400)",)
20-06-2018 12:22:48 Unable to generate token.
20-06-2018 12:22:48 'password' must be specified.
20-06-2018 12:22:48   ("Unable to generate token.\n'password' must be specified.\n(Error Code: 400)",)
                      ERROR: Failed to create group Engineering
                      Traceback:
                        File "C:\Program Files\ArcGIS\Pro\bin\Python\envs\arcgispro-py3\lib\site-packages\arcgis\gis\__init__.py", line 262, in __init__
                          client_id=self._client_id)
                        File "C:\Program Files\ArcGIS\Pro\bin\Python\envs\arcgispro-py3\lib\site-packages\arcgis\_impl\portalpy.py", line 163, in __init__
                          client_id=client_id)
                        File "C:\Program Files\ArcGIS\Pro\bin\Python\envs\arcgispro-py3\lib\site-packages\arcgis\_impl\connection.py", line 284, in __init__
                          self.login(username, password, expiration, client_id)
                        File "C:\Program Files\ArcGIS\Pro\bin\Python\envs\arcgispro-py3\lib\site-packages\arcgis\_impl\connection.py", line 532, in login
                          newtoken = self.generate_token(username, password, expiration, client_id)
                        File "C:\Program Files\ArcGIS\Pro\bin\Python\envs\arcgispro-py3\lib\site-packages\arcgis\_impl\connection.py", line 397, in generate_token
                          ssl=True, add_token=False)
                        File "C:\Program Files\ArcGIS\Pro\bin\Python\envs\arcgispro-py3\lib\site-packages\arcgis\_impl\connection.py", line 1131, in post
                          self._handle_json_error(resp_json['error'], errorcode)
                        File "C:\Program Files\ArcGIS\Pro\bin\Python\envs\arcgispro-py3\lib\site-packages\arcgis\_impl\connection.py", line 1151, in _handle_json_error
                          raise RuntimeError(errormessage)
                        RuntimeError: Unable to generate token.
                        'password' must be specified.
                        (Error Code: 400)
                        During handling of the above exception, another exception occurred:
                        File "PortalAdmin11.py", line 275, in createGroups
                          for extgrp in gisInfo.allGroups:
                        File "PortalAdmin11.py", line 55, in allGroups
                          self._allGroups = self.gis.groups.search()
                        File "PortalAdmin11.py", line 41, in gis
                          self._gis = GIS(self.url, self.username, self.password, verify_cert=False)
                        File "C:\Program Files\ArcGIS\Pro\bin\Python\envs\arcgispro-py3\lib\site-packages\arcgis\gis\__init__.py", line 269, in __init__
                          raise RuntimeError(e.args)
                        RuntimeError: ("Unable to generate token.\n'password' must be specified.\n(Error Code: 400)",)
20-06-2018 12:22:49 Unable to generate token.
20-06-2018 12:22:49 'password' must be specified.
20-06-2018 12:22:49   ("Unable to generate token.\n'password' must be specified.\n(Error Code: 400)",)
                      ERROR: Failed to create group Star Trek:TOS
                      Traceback:
                        File "C:\Program Files\ArcGIS\Pro\bin\Python\envs\arcgispro-py3\lib\site-packages\arcgis\gis\__init__.py", line 262, in __init__
                          client_id=self._client_id)
                        File "C:\Program Files\ArcGIS\Pro\bin\Python\envs\arcgispro-py3\lib\site-packages\arcgis\_impl\portalpy.py", line 163, in __init__
                          client_id=client_id)
                        File "C:\Program Files\ArcGIS\Pro\bin\Python\envs\arcgispro-py3\lib\site-packages\arcgis\_impl\connection.py", line 284, in __init__
                          self.login(username, password, expiration, client_id)
                        File "C:\Program Files\ArcGIS\Pro\bin\Python\envs\arcgispro-py3\lib\site-packages\arcgis\_impl\connection.py", line 532, in login
                          newtoken = self.generate_token(username, password, expiration, client_id)
                        File "C:\Program Files\ArcGIS\Pro\bin\Python\envs\arcgispro-py3\lib\site-packages\arcgis\_impl\connection.py", line 397, in generate_token
                          ssl=True, add_token=False)
                        File "C:\Program Files\ArcGIS\Pro\bin\Python\envs\arcgispro-py3\lib\site-packages\arcgis\_impl\connection.py", line 1131, in post
                          self._handle_json_error(resp_json['error'], errorcode)
                        File "C:\Program Files\ArcGIS\Pro\bin\Python\envs\arcgispro-py3\lib\site-packages\arcgis\_impl\connection.py", line 1151, in _handle_json_error
                          raise RuntimeError(errormessage)
                        RuntimeError: Unable to generate token.
                        'password' must be specified.
                        (Error Code: 400)
                        During handling of the above exception, another exception occurred:
                        File "PortalAdmin11.py", line 275, in createGroups
                          for extgrp in gisInfo.allGroups:
                        File "PortalAdmin11.py", line 55, in allGroups
                          self._allGroups = self.gis.groups.search()
                        File "PortalAdmin11.py", line 41, in gis
                          self._gis = GIS(self.url, self.username, self.password, verify_cert=False)
                        File "C:\Program Files\ArcGIS\Pro\bin\Python\envs\arcgispro-py3\lib\site-packages\arcgis\gis\__init__.py", line 269, in __init__
                          raise RuntimeError(e.args)
                        RuntimeError: ("Unable to generate token.\n'password' must be specified.\n(Error Code: 400)",)
20-06-2018 12:22:50 Unable to generate token.
20-06-2018 12:22:50 'password' must be specified.
20-06-2018 12:22:50   ("Unable to generate token.\n'password' must be specified.\n(Error Code: 400)",)
                      ERROR: Failed to create group Star Trek:Enterprise
                      Traceback:
                        File "C:\Program Files\ArcGIS\Pro\bin\Python\envs\arcgispro-py3\lib\site-packages\arcgis\gis\__init__.py", line 262, in __init__
                          client_id=self._client_id)
                        File "C:\Program Files\ArcGIS\Pro\bin\Python\envs\arcgispro-py3\lib\site-packages\arcgis\_impl\portalpy.py", line 163, in __init__
                          client_id=client_id)
                        File "C:\Program Files\ArcGIS\Pro\bin\Python\envs\arcgispro-py3\lib\site-packages\arcgis\_impl\connection.py", line 284, in __init__
                          self.login(username, password, expiration, client_id)
                        File "C:\Program Files\ArcGIS\Pro\bin\Python\envs\arcgispro-py3\lib\site-packages\arcgis\_impl\connection.py", line 532, in login
                          newtoken = self.generate_token(username, password, expiration, client_id)
                        File "C:\Program Files\ArcGIS\Pro\bin\Python\envs\arcgispro-py3\lib\site-packages\arcgis\_impl\connection.py", line 397, in generate_token
                          ssl=True, add_token=False)
                        File "C:\Program Files\ArcGIS\Pro\bin\Python\envs\arcgispro-py3\lib\site-packages\arcgis\_impl\connection.py", line 1131, in post
                          self._handle_json_error(resp_json['error'], errorcode)
                        File "C:\Program Files\ArcGIS\Pro\bin\Python\envs\arcgispro-py3\lib\site-packages\arcgis\_impl\connection.py", line 1151, in _handle_json_error
                          raise RuntimeError(errormessage)
                        RuntimeError: Unable to generate token.
                        'password' must be specified.
                        (Error Code: 400)
                        During handling of the above exception, another exception occurred:
                        File "PortalAdmin11.py", line 275, in createGroups
                          for extgrp in gisInfo.allGroups:
                        File "PortalAdmin11.py", line 55, in allGroups
                          self._allGroups = self.gis.groups.search()
                        File "PortalAdmin11.py", line 41, in gis
                          self._gis = GIS(self.url, self.username, self.password, verify_cert=False)
                        File "C:\Program Files\ArcGIS\Pro\bin\Python\envs\arcgispro-py3\lib\site-packages\arcgis\gis\__init__.py", line 269, in __init__
                          raise RuntimeError(e.args)
                        RuntimeError: ("Unable to generate token.\n'password' must be specified.\n(Error Code: 400)",)
20-06-2018 12:22:51 Unable to generate token.
20-06-2018 12:22:51 'password' must be specified.
20-06-2018 12:22:51   ("Unable to generate token.\n'password' must be specified.\n(Error Code: 400)",)
                      ERROR: Failed to create group Star Trek:Deep Space Nine
                      Traceback:
                        File "C:\Program Files\ArcGIS\Pro\bin\Python\envs\arcgispro-py3\lib\site-packages\arcgis\gis\__init__.py", line 262, in __init__
                          client_id=self._client_id)
                        File "C:\Program Files\ArcGIS\Pro\bin\Python\envs\arcgispro-py3\lib\site-packages\arcgis\_impl\portalpy.py", line 163, in __init__
                          client_id=client_id)
                        File "C:\Program Files\ArcGIS\Pro\bin\Python\envs\arcgispro-py3\lib\site-packages\arcgis\_impl\connection.py", line 284, in __init__
                          self.login(username, password, expiration, client_id)
                        File "C:\Program Files\ArcGIS\Pro\bin\Python\envs\arcgispro-py3\lib\site-packages\arcgis\_impl\connection.py", line 532, in login
                          newtoken = self.generate_token(username, password, expiration, client_id)
                        File "C:\Program Files\ArcGIS\Pro\bin\Python\envs\arcgispro-py3\lib\site-packages\arcgis\_impl\connection.py", line 397, in generate_token
                          ssl=True, add_token=False)
                        File "C:\Program Files\ArcGIS\Pro\bin\Python\envs\arcgispro-py3\lib\site-packages\arcgis\_impl\connection.py", line 1131, in post
                          self._handle_json_error(resp_json['error'], errorcode)
                        File "C:\Program Files\ArcGIS\Pro\bin\Python\envs\arcgispro-py3\lib\site-packages\arcgis\_impl\connection.py", line 1151, in _handle_json_error
                          raise RuntimeError(errormessage)
                        RuntimeError: Unable to generate token.
                        'password' must be specified.
                        (Error Code: 400)
                        During handling of the above exception, another exception occurred:
                        File "PortalAdmin11.py", line 275, in createGroups
                          for extgrp in gisInfo.allGroups:
                        File "PortalAdmin11.py", line 55, in allGroups
                          self._allGroups = self.gis.groups.search()
                        File "PortalAdmin11.py", line 41, in gis
                          self._gis = GIS(self.url, self.username, self.password, verify_cert=False)
                        File "C:\Program Files\ArcGIS\Pro\bin\Python\envs\arcgispro-py3\lib\site-packages\arcgis\gis\__init__.py", line 269, in __init__
                          raise RuntimeError(e.args)
                        RuntimeError: ("Unable to generate token.\n'password' must be specified.\n(Error Code: 400)",)
20-06-2018 12:22:52 Unable to generate token.
20-06-2018 12:22:52 'password' must be specified.
20-06-2018 12:22:52   ("Unable to generate token.\n'password' must be specified.\n(Error Code: 400)",)
                      ERROR: Failed to create group Star Trek:Voyager
                      Traceback:
                        File "C:\Program Files\ArcGIS\Pro\bin\Python\envs\arcgispro-py3\lib\site-packages\arcgis\gis\__init__.py", line 262, in __init__
                          client_id=self._client_id)
                        File "C:\Program Files\ArcGIS\Pro\bin\Python\envs\arcgispro-py3\lib\site-packages\arcgis\_impl\portalpy.py", line 163, in __init__
                          client_id=client_id)
                        File "C:\Program Files\ArcGIS\Pro\bin\Python\envs\arcgispro-py3\lib\site-packages\arcgis\_impl\connection.py", line 284, in __init__
                          self.login(username, password, expiration, client_id)
                        File "C:\Program Files\ArcGIS\Pro\bin\Python\envs\arcgispro-py3\lib\site-packages\arcgis\_impl\connection.py", line 532, in login
                          newtoken = self.generate_token(username, password, expiration, client_id)
                        File "C:\Program Files\ArcGIS\Pro\bin\Python\envs\arcgispro-py3\lib\site-packages\arcgis\_impl\connection.py", line 397, in generate_token
                          ssl=True, add_token=False)
                        File "C:\Program Files\ArcGIS\Pro\bin\Python\envs\arcgispro-py3\lib\site-packages\arcgis\_impl\connection.py", line 1131, in post
                          self._handle_json_error(resp_json['error'], errorcode)
                        File "C:\Program Files\ArcGIS\Pro\bin\Python\envs\arcgispro-py3\lib\site-packages\arcgis\_impl\connection.py", line 1151, in _handle_json_error
                          raise RuntimeError(errormessage)
                        RuntimeError: Unable to generate token.
                        'password' must be specified.
                        (Error Code: 400)
                        During handling of the above exception, another exception occurred:
                        File "PortalAdmin11.py", line 275, in createGroups
                          for extgrp in gisInfo.allGroups:
                        File "PortalAdmin11.py", line 55, in allGroups
                          self._allGroups = self.gis.groups.search()
                        File "PortalAdmin11.py", line 41, in gis
                          self._gis = GIS(self.url, self.username, self.password, verify_cert=False)
                        File "C:\Program Files\ArcGIS\Pro\bin\Python\envs\arcgispro-py3\lib\site-packages\arcgis\gis\__init__.py", line 269, in __init__
                          raise RuntimeError(e.args)
                        RuntimeError: ("Unable to generate token.\n'password' must be specified.\n(Error Code: 400)",)
20-06-2018 12:22:53 Unable to generate token.
20-06-2018 12:22:53 'password' must be specified.
20-06-2018 12:22:53   ("Unable to generate token.\n'password' must be specified.\n(Error Code: 400)",)
                      ERROR: Failed to create group Star Trek:Discovery
                      Traceback:
                        File "C:\Program Files\ArcGIS\Pro\bin\Python\envs\arcgispro-py3\lib\site-packages\arcgis\gis\__init__.py", line 262, in __init__
                          client_id=self._client_id)
                        File "C:\Program Files\ArcGIS\Pro\bin\Python\envs\arcgispro-py3\lib\site-packages\arcgis\_impl\portalpy.py", line 163, in __init__
                          client_id=client_id)
                        File "C:\Program Files\ArcGIS\Pro\bin\Python\envs\arcgispro-py3\lib\site-packages\arcgis\_impl\connection.py", line 284, in __init__
                          self.login(username, password, expiration, client_id)
                        File "C:\Program Files\ArcGIS\Pro\bin\Python\envs\arcgispro-py3\lib\site-packages\arcgis\_impl\connection.py", line 532, in login
                          newtoken = self.generate_token(username, password, expiration, client_id)
                        File "C:\Program Files\ArcGIS\Pro\bin\Python\envs\arcgispro-py3\lib\site-packages\arcgis\_impl\connection.py", line 397, in generate_token
                          ssl=True, add_token=False)
                        File "C:\Program Files\ArcGIS\Pro\bin\Python\envs\arcgispro-py3\lib\site-packages\arcgis\_impl\connection.py", line 1131, in post
                          self._handle_json_error(resp_json['error'], errorcode)
                        File "C:\Program Files\ArcGIS\Pro\bin\Python\envs\arcgispro-py3\lib\site-packages\arcgis\_impl\connection.py", line 1151, in _handle_json_error
                          raise RuntimeError(errormessage)
                        RuntimeError: Unable to generate token.
                        'password' must be specified.
                        (Error Code: 400)
                        During handling of the above exception, another exception occurred:
                        File "PortalAdmin11.py", line 275, in createGroups
                          for extgrp in gisInfo.allGroups:
                        File "PortalAdmin11.py", line 55, in allGroups
                          self._allGroups = self.gis.groups.search()
                        File "PortalAdmin11.py", line 41, in gis
                          self._gis = GIS(self.url, self.username, self.password, verify_cert=False)
                        File "C:\Program Files\ArcGIS\Pro\bin\Python\envs\arcgispro-py3\lib\site-packages\arcgis\gis\__init__.py", line 269, in __init__
                          raise RuntimeError(e.args)
                        RuntimeError: ("Unable to generate token.\n'password' must be specified.\n(Error Code: 400)",)
20-06-2018 12:22:54 Unable to generate token.
20-06-2018 12:22:54 'password' must be specified.
20-06-2018 12:22:54   ("Unable to generate token.\n'password' must be specified.\n(Error Code: 400)",)
                      ERROR: Failed to create group Star Trek:TNG
                      Traceback:
                        File "C:\Program Files\ArcGIS\Pro\bin\Python\envs\arcgispro-py3\lib\site-packages\arcgis\gis\__init__.py", line 262, in __init__
                          client_id=self._client_id)
                        File "C:\Program Files\ArcGIS\Pro\bin\Python\envs\arcgispro-py3\lib\site-packages\arcgis\_impl\portalpy.py", line 163, in __init__
                          client_id=client_id)
                        File "C:\Program Files\ArcGIS\Pro\bin\Python\envs\arcgispro-py3\lib\site-packages\arcgis\_impl\connection.py", line 284, in __init__
                          self.login(username, password, expiration, client_id)
                        File "C:\Program Files\ArcGIS\Pro\bin\Python\envs\arcgispro-py3\lib\site-packages\arcgis\_impl\connection.py", line 532, in login
                          newtoken = self.generate_token(username, password, expiration, client_id)
                        File "C:\Program Files\ArcGIS\Pro\bin\Python\envs\arcgispro-py3\lib\site-packages\arcgis\_impl\connection.py", line 397, in generate_token
                          ssl=True, add_token=False)
                        File "C:\Program Files\ArcGIS\Pro\bin\Python\envs\arcgispro-py3\lib\site-packages\arcgis\_impl\connection.py", line 1131, in post
                          self._handle_json_error(resp_json['error'], errorcode)
                        File "C:\Program Files\ArcGIS\Pro\bin\Python\envs\arcgispro-py3\lib\site-packages\arcgis\_impl\connection.py", line 1151, in _handle_json_error
                          raise RuntimeError(errormessage)
                        RuntimeError: Unable to generate token.
                        'password' must be specified.
                        (Error Code: 400)
                        During handling of the above exception, another exception occurred:
                        File "PortalAdmin11.py", line 275, in createGroups
                          for extgrp in gisInfo.allGroups:
                        File "PortalAdmin11.py", line 55, in allGroups
                          self._allGroups = self.gis.groups.search()
                        File "PortalAdmin11.py", line 41, in gis
                          self._gis = GIS(self.url, self.username, self.password, verify_cert=False)
                        File "C:\Program Files\ArcGIS\Pro\bin\Python\envs\arcgispro-py3\lib\site-packages\arcgis\gis\__init__.py", line 269, in __init__
                          raise RuntimeError(e.args)
                        RuntimeError: ("Unable to generate token.\n'password' must be specified.\n(Error Code: 400)",)
20-06-2018 12:22:54 Creating users
20-06-2018 12:26:44 ********************************************************************************
20-06-2018 12:26:44 Working on SSL Certificate
20-06-2018 12:26:44   Checking registered SSL Certificate
20-06-2018 12:26:50   Checking if SSL Certificate exists
20-06-2018 12:26:50   Editing existing SSL Protocols & Cipher Suites
20-06-2018 12:26:52   Certificate with alias "portal" is already installed as the portal certificate
20-06-2018 12:26:52 Creating roles
20-06-2018 12:26:52   Creating role: ST User
20-06-2018 12:26:53   Creating role: ST Viewer
20-06-2018 12:26:54   Creating role: ST Captain
20-06-2018 12:26:55   Creating role: ST Engineer
20-06-2018 12:26:56   Creating role: ST Publisher
20-06-2018 12:26:57 Creating groups
20-06-2018 12:26:57   Creating group: ST Captain
20-06-2018 12:27:00   Creating group: ST User
20-06-2018 12:27:00     waiting for group "ST User" to be created
20-06-2018 12:28:22   Creating group: The Carousel
20-06-2018 12:28:23   Creating group: Away Team
20-06-2018 12:28:23     waiting for group "Away Team" to be created
20-06-2018 12:28:29   Creating group: Crew
20-06-2018 12:28:30     waiting for group "Crew" to be created
20-06-2018 12:28:35   Creating group: Engineering
20-06-2018 12:28:36     waiting for group "Engineering" to be created
20-06-2018 12:28:41   Creating group: Star Trek:TOS
20-06-2018 12:28:43     waiting for group "Star Trek:TOS" to be created
20-06-2018 12:28:48   Creating group: Star Trek:Enterprise
20-06-2018 12:28:48     waiting for group "Star Trek:Enterprise" to be created
20-06-2018 12:28:54   Creating group: Star Trek:Deep Space Nine
20-06-2018 12:28:56     waiting for group "Star Trek:Deep Space Nine" to be created
20-06-2018 12:29:01   Creating group: Star Trek:Voyager
20-06-2018 12:29:02     waiting for group "Star Trek:Voyager" to be created
20-06-2018 12:29:07   Creating group: Star Trek:Discovery
20-06-2018 12:29:08     waiting for group "Star Trek:Discovery" to be created
20-06-2018 12:29:13   Creating group: Star Trek:TNG
20-06-2018 12:29:14     waiting for group "Star Trek:TNG" to be created
20-06-2018 12:29:19 Creating users
20-06-2018 12:29:20   Creating user kirk, role ST Captain
20-06-2018 12:29:24     Assigning role: ST Captain
20-06-2018 12:29:25     Adding to groups:
20-06-2018 12:29:26       added to group "Star Trek:TOS"
20-06-2018 12:29:26   Creating user picard, role ST Captain
20-06-2018 12:29:30     Assigning role: ST Captain
20-06-2018 12:29:30     Adding to groups:
20-06-2018 12:29:31       added to group "Star Trek:TNG"
20-06-2018 12:29:31   Creating user archer, role ST Captain
20-06-2018 12:29:34     Assigning role: ST Captain
20-06-2018 12:29:35     Adding to groups:
20-06-2018 12:29:36       added to group "Star Trek:Discovery"
20-06-2018 12:29:36   Creating user janeway, role ST Captain
20-06-2018 12:29:40     Assigning role: ST Captain
20-06-2018 12:29:40     Adding to groups:
20-06-2018 12:29:41       added to group "Star Trek:Voyager"
20-06-2018 12:29:41   Creating user sisko, role ST Captain
20-06-2018 12:29:45     Assigning role: ST Captain
20-06-2018 12:29:46     Adding to groups:
20-06-2018 12:29:46       added to group "Star Trek:Deep Space Nine"
20-06-2018 12:29:46 Configuration security options
20-06-2018 12:29:47   Current default role: account_user
20-06-2018 12:29:50 Configuring general properties
20-06-2018 12:29:50 Configuring system properties
20-06-2018 12:29:51   No system properties require changing
20-06-2018 12:29:51 Script completed successfully
